Workbook

Sheet Modelo financiero
K1: Decisiones financieras estratégicas
K2: Especialización en Ingeniería Financiera
K3: Proyecto final - Valor de las acciones de Chedraui
K4: Fajardo Aguilar Daniel
K5: Mayo de 2023
B7: Modelo financiero Chedraui
B8: Periodo | C8: =D8-1 -> -7 | D8: =E8-1 -> -6 | E8: =F8-1 -> -5 | F8: =G8-1 -> -4 | G8: =H8-1 -> -3 | H8: =I8-1 -> -2 | I8: =J8-1 -> -1 | J8: =K8-1 -> 0 | K8: 1 | L8: =K8+1 -> 2 | M8: =L8+1 -> 3 | N8: =M8+1 -> 4 | O8: =N8+1 -> 5 | P8: =O8+1 -> 6 | Q8: =P8+1 -> 7 | R8: =Q8+1 -> 8 | S8: =R8+1 -> 9 | ... Y8: =X8+1 -> 15 | Z8: n
B9: Concepto | C9: ='Estado de resultados'!C31 -> 2015 | D9: ='Estado de resultados'!D31 -> 2016 | E9: ='Estado de resultados'!E31 -> 2017 | F9: ='Estado de resultados'!F31 -> 2018 | G9: ='Estado de resultados'!G31 -> 2019 | H9: ='Estado de resultados'!H31 -> 2020 | I9: ='Estado de resultados'!I31 -> 2021 | J9: ='Estado de resultados'!J31 -> 2022 | K9: 2023 | L9: =K9+1 -> 2024 | M9: =L9+1 -> 2025 | N9: =M9+1 -> 2026 | O9: =N9+1 -> 2027 | P9: =O9+1 -> 2028 | Q9: =P9+1 -> 2029 | R9: =Q9+1 -> 2030 | S9: =R9+1 -> 2031 | ... Y9: =X9+1 -> 2037
B10: Ingresos | C10: ='Estado de resultados'!C32 -> 117861.89 | D10: ='Estado de resultados'!D32 -> 128579.52 | E10: ='Estado de resultados'!E32 -> 129124.71 | F10: ='Estado de resultados'!F32 -> 151524.88 | G10: ='Estado de resultados'!G32 -> 164664.44 | H10: =Información!C9 -> 180766.85 | I10: =Información!D9 -> 203226.68 | J10: =Información!E9 -> 259326 | K10: =Información!F9 -> 275920.33 | L10: =Información!G9 -> 293612.1 | M10: =Información!H9 -> 312476.74 | N10: =Información!I9 -> 332595.14 | O10: =Información!J9 -> 354054.05 | ... Y10: =Información!T9 -> 644061.05 | Z10: 644061.05
B11: Costos | C11: ='Estado de resultados'!C33+'Estado de resultados'!C35 -> 112348.54 | D11: ='Estado de resultados'!D33+'Estado de resultados'!D35 -> 122399.56 | E11: ='Estado de resultados'!E33+'Estado de resultados'!E35 -> 123091.89 | F11: ='Estado de resultados'!F33+'Estado de resultados'!F35 -> 144783.83 | G11: ='Estado de resultados'!G33+'Estado de resultados'!G35 -> 157571.21 | H11: =Información!C17 -> 172199.74 | I11: =Información!D17 -> 193794.59 | J11: =Información!E17 -> 245580 | K11: =Información!F17 -> 262954.19 | L11: =Información!G17 -> 279814.58 | M11: =Información!H17 -> 297792.73 | N11: =Información!I17 -> 316965.72 | O11: =Información!J17 -> 337416.22 | ... Y11: =Información!T17 -> 613795.12 | Z11: 613795.12
B12: Utilidad Bruta | C12: =C10-C11 -> 5513.3494 | D12: =D10-D11 -> 6179.962 | E12: =E10-E11 -> 6032.8188 | F12: =F10-F11 -> 6741.0558 | G12: =G10-G11 -> 7093.2296 | H12: =H10-H11 -> 8567.1081 | I12: =I10-I11 -> 9432.0936 | J12: =J10-J11 -> 13746 | ... Y12: =Y10-Y11 -> 30265.936 | Z12: 30265.936
C13: =C12/C10 -> 0.046778049 | D13: =D12/D10 -> 0.048063346 | E13: =E12/E10 -> 0.04672087 | F13: =F12/F10 -> 0.044488111 | G13: =G12/G10 -> 0.043076876 | H13: =H12/H10 -> 0.047393138 | I13: =I12/I10 -> 0.046411689 | J13: =J12/J10 -> 0.05300664
B14: Depreciación | C14: ='Flujo de efectivo'!C10 -> 1982.3915 | D14: ='Flujo de efectivo'!D10 -> 2218.6165 | E14: ='Flujo de efectivo'!E10 -> 2234.3218 | F14: ='Flujo de efectivo'!F10 -> 3986.5314 | G14: ='Flujo de efectivo'!G10 -> 4516.0326 | H14: ='Flujo de efectivo'!H10 -> 4694.2439 | I14: ='Flujo de efectivo'!I10 -> 5822.5366 | J14: ='Flujo de efectivo'!J10 -> 7680.74 | K14: =AVERAGE($C$14:$J$14) -> 4141.9268 | L14: =AVERAGE($C$14:$J$14) -> 4141.9268 | M14: =AVERAGE($C$14:$J$14) -> 4141.9268 | N14: =AVERAGE($C$14:$J$14) -> 4141.9268 | O14: =AVERAGE($C$14:$J$14) -> 4141.9268 | P14: =AVERAGE($C$14:$J$14) -> 4141.9268 | Q14: =AVERAGE($C$14:$J$14) -> 4141.9268 | R14: =AVERAGE($C$14:$J$14) -> 4141.9268 | ... Y14: =AVERAGE($C$14:$J$14) -> 4141.9268 | Z14: 4141.9268
B15: Utilidad antes de impuestos | C15: ='Flujo de efectivo'!C8 -> 3955.0931 | D15: ='Flujo de efectivo'!D8 -> 4462.9202 | E15: ='Flujo de efectivo'!E8 -> 4419.8978 | F15: ='Flujo de efectivo'!F8 -> 3179.527 | G15: ='Flujo de efectivo'!G8 -> 3135.8792 | H15: ='Flujo de efectivo'!H8 -> 4630.8475 | I15: ='Flujo de efectivo'!I8 -> 5336.5779 | J15: ='Flujo de efectivo'!J8 -> 8722.151 | K15: =K12-K14 -> 8824.2153 | L15: =L12-L14 -> 9655.5927 | M15: =M12-M14 -> 10542.086 | N15: =N12-N14 -> 11487.497 | O15: =O12-O14 -> 12495.902 | P15: =P12-P14 -> 13496.494 | Q15: =Q12-Q14 -> 14563.326 | R15: =R12-R14 -> 15701.08 | ... Y15: =Y12-Y14 -> 26124.009 | Z15: 26124.009
B16: Impuestos | C16: ='Estado de resultados'!C44 -> 1273.81 | D16: ='Estado de resultados'!D44 -> 1543.9012 | E16: ='Estado de resultados'!E44 -> 1529.024 | F16: ='Estado de resultados'!F44 -> 1107.4032 | G16: ='Estado de resultados'!G44 -> 1180.5088 | H16: ='Estado de resultados'!H44 -> 1325.9061 | I16: ='Estado de resultados'!I44 -> 1583.8758 | J16: ='Estado de resultados'!J44 -> 2546 | K16: =Información!D53 -> 3268.0261 | L16: =Información!E53 -> 3597.5106 | M16: =Información!F53 -> 3927.1667 | N16: =Información!G53 -> 4278.7362 | O16: =Información!H53 -> 4653.7357 | P16: =Información!I53 -> 5023.7206 | Q16: =Información!J53 -> 5420.4355 | R16: =Información!K53 -> 5843.5324 | ... Y16: =Información!R53 -> 9719.8189 | Z16: 9719.8189
B17: Utilidad después de impuestos (Utilidad Neta) | C17: ='Estado de resultados'!C45 -> 2682.494 | D17: ='Estado de resultados'!D45 -> 2919.324 | E17: ='Estado de resultados'!E45 -> 2890.1284 | F17: ='Estado de resultados'!F45 -> 2071.1574 | G17: ='Estado de resultados'!G45 -> 1955.2177 | H17: ='Estado de resultados'!H45 -> 3304.2618 | I17: ='Estado de resultados'!I45 -> 3752.136 | J17: ='Estado de resultados'!J45 -> 6176 | K17: =K15-K16 -> 5556.1892 | L17: =L15-L16 -> 6058.0821 | M17: =M15-M16 -> 6614.9195 | N17: =N15-N16 -> 7208.7608 | O17: =O15-O16 -> 7842.1659 | P17: =P15-P16 -> 8472.7735 | Q17: =Q15-Q16 -> 9142.8903 | R17: =R15-R16 -> 9857.548 | ... Y17: =Y15-Y16 -> 16404.19 | Z17: 16404.19
B18: Inversiones | C18: ='Flujo de efectivo'!C40 -> -4098.3338 | D18: ='Flujo de efectivo'!D40 -> -4877.1519 | E18: ='Flujo de efectivo'!E40 -> -4223.2175 | F18: ='Flujo de efectivo'!F40 -> -11544.304 | G18: ='Flujo de efectivo'!G40 -> -3618.9006 | H18: ='Flujo de efectivo'!H40 -> -3133.7772 | I18: ='Flujo de efectivo'!I40 -> -16843.257 | J18: ='Flujo de efectivo'!J40 -> -6480.844 | K18: =K10*1% -> 2759.2033 | L18: =L10*1% -> 2936.121 | M18: =M10*1% -> 3124.7674 | N18: =N10*1% -> 3325.9514 | O18: =O10*1% -> 3540.5405 | P18: =P10*1% -> 3753.4673 | Q18: =Q10*1% -> 3980.4897 | R18: =R10*1% -> 4222.6046 | ... Y18: =Y10*1% -> 6440.6105 | Z18: 6440.6105
B19: Depreciación | C19: =C14 -> 1982.3915 | D19: =D14 -> 2218.6165 | E19: =E14 -> 2234.3218 | F19: =F14 -> 3986.5314 | G19: =G14 -> 4516.0326 | H19: =H14 -> 4694.2439 | I19: =I14 -> 5822.5366 | J19: =J14 -> 7680.74 | ... Y19: =Y14 -> 4141.9268 | Z19: 4141.9268
B20: Capital de trabajo | C20: ='Balance general'!C68-'Balance general'!C90 -> -9354.2612 | D20: ='Balance general'!D68-'Balance general'!D90 -> -8466.0396 | E20: ='Balance general'!E68-'Balance general'!E90 -> -6406.8836 | F20: ='Balance general'!F68-'Balance general'!F90 -> -7433.1828 | G20: ='Balance general'!G68-'Balance general'!G90 -> -8103.277 | H20: ='Balance general'!H68-'Balance general'!H90 -> -7994.979 | I20: ='Balance general'!I68-'Balance general'!I90 -> -6800.2074 | J20: ='Balance general'!J68-'Balance general'!J90 -> -5446 | K20: =Información!D62 -> -1351.694 | L20: =Información!E62 -> -1441.0856 | M20: =Información!F62 -> -1536.6223 | N20: =Información!G62 -> -1638.7477 | O20: =Información!H62 -> -1747.9392 | P20: =Información!I62 -> -1734.3981 | Q20: =Información!J62 -> -1849.2152 | R20: =Información!K62 -> -1972.1508 | ... Y20: =Información!R62 -> -3116.3455 | Z20: -3116.3455
B21: Flujo disponible para el servicio de la deuda | C21: =C17-C18+C19+C20 -> -591.04185 | D21: =D17-D18+D19+D20 -> 1549.0529 | E21: =E17-E18+E19+E20 -> 2940.7841 | F21: =F17-F18+F19+F20 -> 10168.81 | G21: =G17-G18+G19+G20 -> 1986.8739 | H21: =H17-H18+H19+H20 -> 3137.3039 | I21: =I17-I18+I19+I20 -> 19617.722 | J21: =J17-J18+J19+J20 -> 14891.584 | ... Y21: =Y17-Y18+Y19+Y20 -> 10989.161 | Z21: 10989.161
B22: Servicio de la deuda | J22: =Información!C44 -> 12652.687 | K22: =Información!D44 -> 9467.3283 | L22: =Información!E44 -> 6060.2048 | M22: =Información!F44 -> 2415.8719 | N22: =AVERAGE($J$22:$M$22) -> 7649.0231 | O22: =AVERAGE($J$22:$M$22) -> 7649.0231 | P22: =AVERAGE($J$22:$M$22) -> 7649.0231 | Q22: =AVERAGE($J$22:$M$22) -> 7649.0231 | R22: =AVERAGE($J$22:$M$22) -> 7649.0231 | S22: =AVERAGE($J$22:$M$22) -> 7649.0231 | T22: =AVERAGE($J$22:$M$22) -> 7649.0231 | U22: =AVERAGE($J$22:$M$22) -> 7649.0231 | ... Y22: =AVERAGE($J$22:$M$22) -> 7649.0231 | Z22: 7649.0231
B23: Valor de rescate | Y23: =Z21/L35 -> 111193.76
B26: Flujo de Efectivo Libre | C26: =C17-C18+C19+C20 -> -591.04185 | D26: =D17-D18+D19+D20 -> 1549.0529 | E26: =E17-E18+E19+E20 -> 2940.7841 | F26: =F17-F18+F19+F20 -> 10168.81 | G26: =G17-G18+G19+G20 -> 1986.8739 | H26: =H17-H18+H19+H20 -> 3137.3039 | I26: =I17-I18+I19+I20 -> 19617.722 | J26: =J17-J18+J19+J20 -> 14891.584 | K26: =K17-K18+K19+K20 -> 5587.2186 | L26: =L21-L22 -> -237.40251 | M26: =M21-M22 -> 3679.5848 | N26: =N21-N22 -> -1263.0346 | O26: =O21-O22 -> -953.4101 | P26: =P21-P22 -> -522.18811 | Q26: =Q21-Q22 -> -193.91087 | R26: =R21-R22 -> 155.69631 | S26: =S21-S22 -> 528.12334 | ... X26: =X21-X22 -> 2792.7992 | Y26: =Y21-Y22+Y23 -> 114533.9 | Z26: =Z21-Z22 -> 3340.1378
B28: Flujo de Efectivo Libre Descontado | K28: =K26/((1+$L$35)^K8) -> 5084.7028 | L28: =L26/((1+$L$35)^L8) -> -196.61884 | M28: =M26/((1+$L$35)^M8) -> 2773.3747 | N28: =N26/((1+$L$35)^N8) -> -866.35301 | O28: =O26/((1+$L$35)^O8) -> -595.15394 | P28: =P26/((1+$L$35)^P8) -> -296.65144 | Q28: =Q26/((1+$L$35)^Q8) -> -100.25165 | R28: =R26/((1+$L$35)^R8) -> 73.255058 | ... Y28: =Y26/((1+$L$35)^Y8) -> 27860.105
B29: Flujo de Efectivo Libre Descontado Acumulado | K29: =K28 -> 5084.7028 | L29: =K29+L28 -> 4888.084 | M29: =L29+M28 -> 7661.4587 | N29: =M29+N28 -> 6795.1057 | O29: =N29+O28 -> 6199.9518 | P29: =O29+P28 -> 5903.3003 | Q29: =P29+Q28 -> 5803.0487 | R29: =Q29+R28 -> 5876.3037 | S29: =R29+S28 -> 6102.4371 | ... Y29: =X29+Y28 -> 36797.622
K32: RESULTADOS | O32: WACC | P32: =(P33*P34)+(P35*P36)*(1-P37) -> 0.098828934
K33: Valor del Negocio (VPN) | L33: =SUM(K28:Y28) -> 36797.622 | O33: Porcentaje de Capital | P33: 0.70123791
O34: Costo de capital | P34: 0.11200251
K35: Tasa de descuento | L35: =P32 -> 0.098828934 | O35: Porcentaje de Deuda | P35: =1-P33 -> 0.29876209
N36: 8.5 | O36: Costo de la Deuda | P36: 0.097012361
K37: Pasivos financieros (-) | L37: ='Balance general'!J101 -> 104071 | M37: Cost of equity Damodaran | O37: Tasa tributaria | P37: 0.3
K38: Pasivos Laborales (-)
K39: Pasivos contingentes (-)
K40: Tesoreria (+) | L40: ='Balance general'!J68 -> 37695 | M40: activo circulante
K41: Valor de la empresa | L41: =L33-L37-L38-L39+L40 -> -29578.378
K42: No. de acciones en circulación | L42: 963917211
K43: Precio de la acción | L43: =(L41*10^6)/L42 -> -30.6856
O57: Escenario | P57: Valor del negocio | Q57: Precio acción
O58: Base | P58: 36797.622 | Q58: -30.6856
O59: Tasa de descuento = 7.5% | P59: 60617.44 | Q59: -5.9741231
...

Sheet Chedraui
B3: Tiendas en México | E3: Tiendas en Estados Unidos | L3: FORTALEZAS | Q3: OPORTUNIDADES
B4: 205 | C4: Chedraui | E4: 64 | F4: El Super
B5: 75 | C5: Súper Chedraui | E5: 59 | F5: Fiesta | L5: Estrategia de precios bajos. Productos de fabricantes líderes. Empresa líder mexicana de tiendas de autoservicio. Experiencia de compra. | Q5: Expandir la red de tiendas de autoservicio. Estructura organizacional sólida. Nuevos productos de marca propia. Campañas de descuentos/promociones.
B6: 8 | C6: Súper Che | E6: 253 | F6: Smart & Final
B7: 80 | C7: Supercito | E7: =SUM(E4:E6) -> 376
B8: 36 | C8: Arteli
B9: =SUM(B4:B8) -> 404
L13: AMENAZAS | Q13: DEBILIDADES
L15: Mercado altamente competitivo. Negocio altamente dependiente de las economías de México y de Estados Unidos. Ataques cibernéticos. Vencimiento anticipado de créditos. | Q15: Dificultades para obtener mercancía de suficiente calidad a bajo costo. Incapacidad de reaccionar a cambios en la demanda del consumidor. Imposibilidad de mantener relaciones con los sindicatos.

Sheet Información
D1: Incremento anual en ingresos de EUA: | E1: 0.055 | G1: Incremento anual en semento inmobiliario: | H1: =E8/D8-1 -> 0.14388178
D2: Incremento anual en ingresos de México: | E2: =E6/D6-1 -> 0.076285616 | G2: Relación Utilidad/Ingresos | H2: =AVERAGE('Modelo financiero'!$C$13:$J$13) -> 0.04699234 | I2: ='Estado de resultados'!$T$34 -> 0.21416988
B3: Ingresos
B4: ='Modelo financiero'!B8 -> Periodo | C4: ='Modelo financiero'!H8 -> -2 | D4: ='Modelo financiero'!I8 -> -1 | E4: ='Modelo financiero'!J8 -> 0 | F4: ='Modelo financiero'!K8 -> 1 | G4: ='Modelo financiero'!L8 -> 2 | H4: ='Modelo financiero'!M8 -> 3 | I4: ='Modelo financiero'!N8 -> 4 | J4: ='Modelo financiero'!O8 -> 5 | ... T4: ='Modelo financiero'!Y8 -> 15
B5: Ingresos por segmento | C5: ='Modelo financiero'!H9 -> 2020 | D5: ='Modelo financiero'!I9 -> 2021 | E5: ='Modelo financiero'!J9 -> 2022 | F5: ='Modelo financiero'!K9 -> 2023 | G5: ='Modelo financiero'!L9 -> 2024 | H5: ='Modelo financiero'!M9 -> 2025 | I5: ='Modelo financiero'!N9 -> 2026 | J5: ='Modelo financiero'!O9 -> 2027 | ... T5: ='Modelo financiero'!Y9 -> 2037
B6: Operaciones en México | C6: ='Estado de resultados'!H87 -> 101989.74 | D6: ='Estado de resultados'!I87 -> 97316.176 | E6: ='Estado de resultados'!J87 -> 104740 | F6: =E6*(1+$E$2) -> 112730.16 | G6: =F6*(1+$E$2) -> 121329.84 | H6: =G6*(1+$E$2) -> 130585.57 | I6: =H6*(1+$E$2) -> 140547.37 | J6: =I6*(1+$E$2) -> 151269.11 | K6: =J6*(1+$E$2/2) -> 157038.94 | L6: =K6*(1+$E$2/2) -> 163028.84 | M6: =L6*(1+$E$2/2) -> 169247.22 | N6: =M6*(1+$E$2/2) -> 175702.79 | O6: =N6*(1+$E$2/2) -> 182404.58 | P6: =O6*(1+$E$2/2) -> 189362.01 | Q6: =P6*(1+$E$2/2) -> 196584.81 | R6: =Q6*(1+$E$2/2) -> 204083.1 | ... T6: =S6*(1+$E$2/2) -> 219948.62
B7: Operaciones en Estados Unidos | C7: ='Estado de resultados'!H88 -> 77724.294 | D7: ='Estado de resultados'!I88 -> 104907.78 | E7: ='Estado de resultados'!J88 -> 153439 | F7: =E7*(1+$E$1) -> 161878.14 | G7: =F7*(1+$E$1) -> 170781.44 | H7: =G7*(1+$E$1) -> 180174.42 | I7: =H7*(1+$E$1) -> 190084.02 | J7: =I7*(1+$E$1) -> 200538.64 | K7: =J7*(1+$E$2) -> 215836.85 | L7: =K7*(1+$E$2) -> 232302.1 | M7: =L7*(1+$E$2) -> 250023.41 | N7: =M7*(1+$E$2) -> 269096.59 | O7: =N7*(1+$E$2) -> 289624.79 | P7: =O7*(1+$E$2) -> 311719 | Q7: =P7*(1+$E$2) -> 335498.68 | R7: =Q7*(1+$E$2) -> 361092.4 | ... T7: =S7*(1+$E$2) -> 418286.09
B8: Segmento inmobiliario | C8: ='Estado de resultados'!H89 -> 1052.8164 | D8: ='Estado de resultados'!I89 -> 1002.726 | E8: ='Estado de resultados'!J89 -> 1147 | F8: =E8*(1+$H$1) -> 1312.0324 | G8: =F8*(1+$H$1) -> 1500.81 | H8: =G8*(1+$H$1) -> 1716.7492 | I8: =H8*(1+$H$1) -> 1963.7581 | J8: =I8*(1+$H$1) -> 2246.3071 | K8: =J8*(1+10%) -> 2470.9378 | L8: =K8*(1+10%) -> 2718.0316 | M8: =L8*(1+10%) -> 2989.8347 | N8: =M8*(1+10%) -> 3288.8182 | O8: =N8*(1+10%) -> 3617.7 | P8: =O8*(1+10%) -> 3979.47 | Q8: =P8*(1+10%) -> 4377.417 | R8: =Q8*(1+10%) -> 4815.1587 | ... T8: =S8*(1+10%) -> 5826.3421
B9: Total de ingresos | C9: =SUM(C6:C8) -> 180766.85 | D9: =SUM(D6:D8) -> 203226.68 | E9: =SUM(E6:E8) -> 259326 | F9: =SUM(F6:F8) -> 275920.33 | G9: =SUM(G6:G8) -> 293612.1 | H9: =SUM(H6:H8) -> 312476.74 | I9: =SUM(I6:I8) -> 332595.14 | J9: =SUM(J6:J8) -> 354054.05 | ... T9: =SUM(T6:T8) -> 644061.05
B12: Costos
B13: =B4 -> Periodo | C13: =C4 -> -2 | D13: =D4 -> -1 | E13: =E4 -> 0 | F13: =F4 -> 1 | G13: =G4 -> 2 | H13: =H4 -> 3 | I13: =I4 -> 4 | ... T13: =T4 -> 15
C14: =C5 -> 2020 | D14: =D5 -> 2021 | E14: =E5 -> 2022 | F14: =F5 -> 2023 | G14: =G5 -> 2024 | H14: =H5 -> 2025 | I14: =I5 -> 2026 | J14: =J5 -> 2027 | ... T14: =T5 -> 2037
B15: Gastos de operación | C15: ='Estado de resultados'!H35 -> 31443.622 | D15: ='Estado de resultados'!I35 -> 35800.553 | E15: ='Estado de resultados'!J35 -> 45554 | F15: =F17-F16 -> 52590.838 | G15: =G17-G16 -> 55962.916 | H15: =H17-H16 -> 59558.545 | I15: =I17-I16 -> 63393.143 | J15: =J17-J16 -> 67483.245 | K15: =K17-K16 -> 71541.661 | L15: =L17-L16 -> 75868.744 | M15: =M17-M16 -> 80483.491 | ... T15: =T17-T16 -> 122759.02
B16: Costo de ventas | C16: ='Estado de resultados'!H33 -> 140756.12 | D16: ='Estado de resultados'!I33 -> 157994.04 | E16: ='Estado de resultados'!J33 -> 200026 | F16: =F17*0.8 -> 210363.35 | G16: =G17*0.8 -> 223851.66 | H16: =H17*0.8 -> 238234.18 | I16: =I17*0.8 -> 253572.57 | J16: =J17*0.8 -> 269932.98 | K16: =K17*0.8 -> 286166.64 | L16: =L17*0.8 -> 303474.98 | M16: =M17*0.8 -> 321933.96 | ... T16: =T17*0.8 -> 491036.09
B17: Total de costos | C17: =SUM(C15:C16) -> 172199.74 | D17: =SUM(D15:D16) -> 193794.59 | E17: =SUM(E15:E16) -> 245580 | F17: =F9*(1-$H$2) -> 262954.19 | G17: =G9*(1-$H$2) -> 279814.58 | H17: =H9*(1-$H$2) -> 297792.73 | I17: =I9*(1-$H$2) -> 316965.72 | J17: =J9*(1-$H$2) -> 337416.22 | K17: =K9*(1-$H$2) -> 357708.3 | L17: =L9*(1-$H$2) -> 379343.72 | M17: =M9*(1-$H$2) -> 402417.46 | ... T17: =T9*(1-$H$2) -> 613795.12
C21: Crédito 1 | D21: =620*10^6 -> 620000000 | F21: Crédito 2 | G21: =200*10^6 -> 200000000
C22: n | D22: 5 | F22: n | G22: 4
C23: i | D23: 0.0155 | F23: i | G23: 0.0125
C24: Tasa deuda | D24: =D23+D27 -> 0.0705 | F24: Tasa deuda | G24: =G23+D27 -> 0.0675
C25: R | D25: =PMT(D24,D22,-D21) -> 1.5141472e+08 | F25: R | G25: =PMT(G24,G22,-G21) -> 58712734
C27: LIBOR | D27: 0.055 | F27: Tipo de cambio USD | G27: 19.3615
B29: Deuda largo plazo
B30: Periodo | C30: =E4 -> 0 | D30: =F4 -> 1 | E30: =G4 -> 2 | F30: =H4 -> 3 | G30: =I4 -> 4
B31: Amortización 1 | C31: =E5 -> 2022 | D31: =F5 -> 2023 | E31: =G5 -> 2024 | F31: =H5 -> 2025 | G31: =I5 -> 2026
B32: Saldo inicial | C32: =D21 -> 620000000 | D32: =C36 -> 498710000 | E32: =D36 -> 3.8245433e+08 | F32: =E36 -> 2.5800264e+08 | G32: =F36 -> 1.247771e+08
B33: Pago total | C33: =165*10^6 -> 165000000 | D33: =$D$25 -> 1.5141472e+08 | E33: =$D$25 -> 1.5141472e+08 | F33: =$D$25 -> 1.5141472e+08 | G33: =G32+G34 -> 1.3357389e+08
B34: Intereses | C34: =C32*$D$24 -> 43710000 | D34: =D32*$D$24 -> 35159055 | E34: =E32*$D$24 -> 26963030 | F34: =F32*$D$24 -> 18189186 | G34: =G32*$D$24 -> 8796785.7
B35: Capital | C35: =C33-C34 -> 121290000 | D35: =D33-D34 -> 1.1625567e+08 | E35: =E33-E34 -> 1.2445169e+08 | F35: =F33-F34 -> 1.3322554e+08 | G35: =G33-G34 -> 1.247771e+08
B36: Saldo final | C36: =C32-C35 -> 498710000 | D36: =D32-D35 -> 3.8245433e+08 | E36: =E32-E35 -> 2.5800264e+08 | F36: =F32-F35 -> 1.247771e+08 | G36: =G32-G35 -> 0
B37: Amortización 2 | C37: =C31 -> 2022 | D37: =D31 -> 2023 | E37: =E31 -> 2024 | F37: =F31 -> 2025 | G37: =G31 -> 2026
B38: Saldo inicial | C38: =G21 -> 200000000 | D38: =C42 -> 1.5478727e+08 | E38: =D42 -> 1.0652267e+08 | F38: =E42 -> 55000219 | G38: 0
B39: Pago total | C39: =$G$25 -> 58712734 | D39: =$G$25 -> 58712734 | E39: =$G$25 -> 58712734 | F39: =$G$25 -> 58712734 | G39: 0
B40: Intereses | C40: =C38*$G$24 -> 13500000 | D40: =D38*$G$24 -> 10448140 | E40: =E38*$G$24 -> 7190280.4 | F40: =F38*$G$24 -> 3712514.8 | G40: 0
B41: Capital | C41: =C39-C40 -> 45212734 | D41: =D39-D40 -> 48264593 | E41: =E39-E40 -> 51522454 | F41: =F39-F40 -> 55000219 | G41: 0
B42: Saldo final | C42: =C38-C41 -> 1.5478727e+08 | D42: =D38-D41 -> 1.0652267e+08 | E42: =E38-E41 -> 55000219 | F42: =F38-F41 -> 0 | G42: 0
B43: Millones Deuda total, USD | C43: =(C36+C42)/(10^6) -> 653.49727 | D43: =(D36+D42)/(10^6) -> 488.977 | E43: =(E36+E42)/(10^6) -> 313.00286 | F43: =(F36+F42)/(10^6) -> 124.7771 | G43: =(G36+G42)/(10^6) -> 0
B44: Millones Deuda total, MXN | C44: =C43*$G$27 -> 12652.687 | D44: =D43*$G$27 -> 9467.3283 | E44: =E43*$G$27 -> 6060.2048 | F44: =F43*$G$27 -> 2415.8719 | G44: =G43*$G$27 -> 0
B46: Impuestos
C47: =E4 -> 0 | D47: =F4 -> 1 | E47: =G4 -> 2 | F47: =H4 -> 3 | G47: =I4 -> 4 | H47: =J4 -> 5 | I47: =K4 -> 6 | J47: =L4 -> 7 | ... R47: =T4 -> 15
B48: Periodo | C48: =E5 -> 2022 | D48: =F5 -> 2023 | E48: =G5 -> 2024 | F48: =H5 -> 2025 | G48: =I5 -> 2026 | H48: =J5 -> 2027 | I48: =K5 -> 2028 | J48: =L5 -> 2029 | ... R48: =T5 -> 2037
...

Sheet Razones financieras
B3: Liquidez | C3: 2015 | D3: 2016 | E3: 2017 | F3: 2018 | G3: 2019 | H3: 2020 | I3: 2021 | J3: 2022
B4: Solvencia circulante | C4: =C5/C6 -> 0.65308731 | D4: =D5/D6 -> 0.68355049 | E4: =E5/E6 -> 0.74802685 | F4: =F5/F6 -> 0.7631984 | G4: =G5/G6 -> 0.74488366 | H4: =H5/H6 -> 0.76683004 | I4: =I5/I6 -> 0.83636883 | J4: =J5/J6 -> 0.87376278 | K4: La empresa no es capaz de pagar lo que debe en el corto plazo. Ha mejorado su solvencia en los últimos años.
B5: Activo ciruclante | C5: ='Balance general'!C68 -> 17610.049 | D5: ='Balance general'!D68 -> 18287.168 | E5: ='Balance general'!E68 -> 19019.966 | F5: ='Balance general'!F68 -> 23956.735 | G5: ='Balance general'!G68 -> 23659.788 | H5: ='Balance general'!H68 -> 26293.225 | I5: ='Balance general'!I68 -> 34757.933 | J5: ='Balance general'!J68 -> 37695
B6: Pasivo circulante | C6: ='Balance general'!C90 -> 26964.31 | D6: ='Balance general'!D90 -> 26753.208 | E6: ='Balance general'!E90 -> 25426.85 | F6: ='Balance general'!F90 -> 31389.918 | G6: ='Balance general'!G90 -> 31763.065 | H6: ='Balance general'!H90 -> 34288.204 | I6: ='Balance general'!I90 -> 41558.141 | J6: ='Balance general'!J90 -> 43141
B7: Prueba de ácido | C7: =C8/C9 -> 0.23653643 | D7: =D8/D9 -> 0.19809989 | E7: =E8/E9 -> 0.22969128 | F7: =F8/F9 -> 0.22773225 | G7: =G8/G9 -> 0.20537466 | H7: =H8/H9 -> 0.33487098 | I7: =I8/I9 -> 0.37175695 | J7: =J8/J9 -> 0.38608284 | K7: Debido al gran peso de los inventarios, sin su venta, la empresa posee muy baja solvencia para cubrir las obligaciones
B8: Activo circulante - Inventario | C8: =('Balance general'!C68-'Balance general'!C65) -> 6378.0416 | D8: =('Balance general'!D68-'Balance general'!D65) -> 5299.8076 | E8: =('Balance general'!E68-'Balance general'!E65) -> 5840.3256 | F8: =('Balance general'!F68-'Balance general'!F65) -> 7148.4966 | G8: =('Balance general'!G68-'Balance general'!G65) -> 6523.3288 | H8: =('Balance general'!H68-'Balance general'!H65) -> 11482.124 | I8: =('Balance general'!I68-'Balance general'!I65) -> 15449.528 | J8: =('Balance general'!J68-'Balance general'!J65) -> 16656
B9: Pasivo circulante | C9: ='Balance general'!C90 -> 26964.31 | D9: ='Balance general'!D90 -> 26753.208 | E9: ='Balance general'!E90 -> 25426.85 | F9: ='Balance general'!F90 -> 31389.918 | G9: ='Balance general'!G90 -> 31763.065 | H9: ='Balance general'!H90 -> 34288.204 | I9: ='Balance general'!I90 -> 41558.141 | J9: ='Balance general'!J90 -> 43141
B10: Razón pago inmediato | C10: =('Balance general'!C68-'Balance general'!C65-'Balance general'!C61)/'Balance general'!C90 -> 0.19235258 | D10: =('Balance general'!D68-'Balance general'!D65-'Balance general'!D61)/'Balance general'!D90 -> 0.14641694 | E10: =('Balance general'!E68-'Balance general'!E65-'Balance general'!E61)/'Balance general'!E90 -> 0.1753557 | F10: =('Balance general'!F68-'Balance general'!F65-'Balance general'!F61)/'Balance general'!F90 -> 0.16574448 | G10: =('Balance general'!G68-'Balance general'!G65-'Balance general'!G61)/'Balance general'!G90 -> 0.15118747 | H10: =('Balance general'!H68-'Balance general'!H65-'Balance general'!H61)/'Balance general'!H90 -> 0.28661525 | I10: =('Balance general'!I68-'Balance general'!I65-'Balance general'!I61)/'Balance general'!I90 -> 0.31475716 | J10: =('Balance general'!J68-'Balance general'!J65-'Balance general'!J61)/'Balance general'!J90 -> 0.33995503 | K10: En los últimos años Chedraui a incrementado su efectivo pero continua sin la posibilidad de cubrir sus deudas de inmediato (deficiencia de efectivo).
B13: Estabilidad o solvencia | C13: 2015 | D13: 2016 | E13: 2017 | F13: 2018 | G13: 2019 | H13: 2020 | I13: 2021 | J13: 2022
B14: Apalancamiento | C14: =C16/C17 -> 1.0210841 | D14: =D16/D17 -> 0.97791224 | E14: =E16/E17 -> 0.93461593 | F14: =F16/F17 -> 2.2603444 | G14: =G16/G17 -> 2.1883254 | H14: =H16/H17 -> 2.0889625 | I14: =I16/I17 -> 3.3184017 | J14: =J16/J17 -> 2.643543 | K14: Se están utilizando de manera eficiente los recursos de terceros para hacer frente a los compromisos.
B15: Razón pasivo capital | C15: ='Balance general'!C100/'Balance general'!C102 -> 0.3039458 | D15: ='Balance general'!D100/'Balance general'!D102 -> 0.29411983 | E15: ='Balance general'!E100/'Balance general'!E102 -> 0.27954418 | F15: ='Balance general'!F100/'Balance general'!F102 -> 1.3643107 | G15: ='Balance general'!G100/'Balance general'!G102 -> 1.2773805 | H15: ='Balance general'!H100/'Balance general'!H102 -> 1.1413496 | I15: ='Balance general'!I100/'Balance general'!I102 -> 2.1382425 | J15: ='Balance general'!J100/'Balance general'!J102 -> 1.5477037 | K15: La mayor parte del endeudamiento corresponde a largo plazo.
B16: Pasivo total | C16: ='Balance general'!C101 -> 38392.633 | D16: ='Balance general'!D101 -> 38260.573 | E16: ='Balance general'!E101 -> 36277.46 | F16: ='Balance general'!F101 -> 79184.552 | G16: ='Balance general'!G101 -> 76303.102 | H16: ='Balance general'!H101 -> 75586.533 | I16: ='Balance general'!I101 -> 116854.24 | J16: ='Balance general'!J101 -> 104071
B17: Capital contable | C17: ='Balance general'!C102 -> 37599.874 | D17: ='Balance general'!D102 -> 39124.751 | E17: ='Balance general'!E102 -> 38815.366 | F17: ='Balance general'!F102 -> 35032.073 | G17: ='Balance general'!G102 -> 34868.261 | H17: ='Balance general'!H102 -> 36183.767 | I17: ='Balance general'!I102 -> 35214.012 | J17: ='Balance general'!J102 -> 39368
B18: Razón de endeudamiento | C18: =C19/C20 -> 0.505226 | D18: =D19/D20 -> 0.49442568 | E18: =E19/E20 -> 0.48308397 | F18: =F19/F20 -> 0.69326809 | G18: =G19/G20 -> 0.68636358 | H18: =H19/H20 -> 0.67628166 | I18: =I19/I20 -> 0.7684274 | J18: =J19/J20 -> 0.72554187 | K18: Los activos han sido financiados pacticamente por los dueños del negocio.
B19: Pasivo total | C19: ='Balance general'!C101 -> 38392.633 | D19: ='Balance general'!D101 -> 38260.573 | E19: ='Balance general'!E101 -> 36277.46 | F19: ='Balance general'!F101 -> 79184.552 | G19: ='Balance general'!G101 -> 76303.102 | H19: ='Balance general'!H101 -> 75586.533 | I19: ='Balance general'!I101 -> 116854.24 | J19: ='Balance general'!J101 -> 104071
B20: Activo total | C20: ='Balance general'!C79 -> 75991.009 | D20: ='Balance general'!D79 -> 77383.872 | E20: ='Balance general'!E79 -> 75095.556 | F20: ='Balance general'!F79 -> 114219.24 | G20: ='Balance general'!G79 -> 111170.09 | H20: ='Balance general'!H79 -> 111767.83 | I20: ='Balance general'!I79 -> 152069.33 | J20: ='Balance general'!J79 -> 143439
B21: Inversión del capital | C21: ='Balance general'!C78/'Balance general'!C102 -> 1.5526903 | D21: ='Balance general'!D78/'Balance general'!D102 -> 1.5104685 | E21: ='Balance general'!E78/'Balance general'!E102 -> 1.444675 | F21: ='Balance general'!F78/'Balance general'!F102 -> 2.5765675 | G21: ='Balance general'!G78/'Balance general'!G102 -> 2.509741 | H21: ='Balance general'!H78/'Balance general'!H102 -> 2.3622362 | I21: ='Balance general'!I78/'Balance general'!I102 -> 3.331384 | J21: ='Balance general'!J78/'Balance general'!J102 -> 2.6860394
B22: Valor del capital | C22: ='Balance general'!C102/'Balance general'!C103 -> 99.563492 | D22: ='Balance general'!D102/'Balance general'!D103 -> 106.89683 | E22: ='Balance general'!E102/'Balance general'!E103 -> 112.8254 | F22: ='Balance general'!F102/'Balance general'!F103 -> 106.45238 | G22: ='Balance general'!G102/'Balance general'!G103 -> 108.76984 | H22: ='Balance general'!H102/'Balance general'!H103 -> 116.19841 | I22: ='Balance general'!I102/'Balance general'!I103 -> 129.60317 | J22: ='Balance general'!J102/'Balance general'!J103 -> 156.22222
B23: Productividad | C23: 2015 | D23: 2016 | E23: 2017 | F23: 2018 | G23: 2019 | H23: 2020 | I23: 2021 | J23: 2022
B24: Rotación de activos fijos netos | C24: ='Estado de resultados'!C32/'Balance general'!C78 -> 2.0188413 | D24: ='Estado de resultados'!D32/'Balance general'!D78 -> 2.1757477 | E24: ='Estado de resultados'!E32/'Balance general'!E78 -> 2.3026902 | F24: ='Estado de resultados'!F32/'Balance general'!F78 -> 1.6787135 | G24: ='Estado de resultados'!G32/'Balance general'!G78 -> 1.8816578 | H24: ='Estado de resultados'!H32/'Balance general'!H78 -> 2.1148603 | I24: ='Estado de resultados'!I32/'Balance general'!I78 -> 1.7323695 | J24: ='Estado de resultados'!J32/'Balance general'!J78 -> 2.4523945 | K24: La empresa emplea su planta y equipo de forma eficiente.
B25: Ingresos | C25: ='Estado de resultados'!C32 -> 117861.89 | D25: ='Estado de resultados'!D32 -> 128579.52 | E25: ='Estado de resultados'!E32 -> 129124.71 | F25: ='Estado de resultados'!F32 -> 151524.88 | G25: ='Estado de resultados'!G32 -> 164664.44 | H25: ='Estado de resultados'!H32 -> 180766.85 | I25: ='Estado de resultados'!I32 -> 203226.68 | J25: ='Estado de resultados'!J32 -> 259326
B26: Activos fijos | C26: ='Balance general'!C78 -> 58380.96 | D26: ='Balance general'!D78 -> 59096.704 | E26: ='Balance general'!E78 -> 56075.59 | F26: ='Balance general'!F78 -> 90262.502 | G26: ='Balance general'!G78 -> 87510.303 | H26: ='Balance general'!H78 -> 85474.605 | I26: ='Balance general'!I78 -> 117311.39 | J26: ='Balance general'!J78 -> 105744
B27: Rotación de activos totales | C27: =C28/C29 -> 1.5509979 | D27: =D28/D29 -> 1.6615803 | E27: =E28/E29 -> 1.7194721 | F27: =F28/F29 -> 1.3266144 | G27: =G28/G29 -> 1.4811937 | H27: =H28/H29 -> 1.6173424 | I27: =I28/I29 -> 1.3364081 | J27: =J28/J29 -> 1.8079183 | K27: Se tiene una buena rotacion de activos, los activos tienen buena capacidad para generar ventas.
B28: Ingresos | C28: ='Estado de resultados'!C32 -> 117861.89 | D28: ='Estado de resultados'!D32 -> 128579.52 | E28: ='Estado de resultados'!E32 -> 129124.71 | F28: ='Estado de resultados'!F32 -> 151524.88 | G28: ='Estado de resultados'!G32 -> 164664.44 | H28: ='Estado de resultados'!H32 -> 180766.85 | I28: ='Estado de resultados'!I32 -> 203226.68 | J28: ='Estado de resultados'!J32 -> 259326
B29: Activo total | C29: ='Balance general'!C79 -> 75991.009 | D29: ='Balance general'!D79 -> 77383.872 | E29: ='Balance general'!E79 -> 75095.556 | F29: ='Balance general'!F79 -> 114219.24 | G29: ='Balance general'!G79 -> 111170.09 | H29: ='Balance general'!H79 -> 111767.83 | I29: ='Balance general'!I79 -> 152069.33 | J29: ='Balance general'!J79 -> 143439
B30: Rotación de capital contable | C30: =C31/C32 -> 3.1346353 | D30: =D31/D32 -> 3.2863984 | E30: =E31/E32 -> 3.326639 | F30: =F31/F32 -> 4.3253187 | G30: =G31/G32 -> 4.7224735 | H30: =H31/H32 -> 4.9957995 | I30: =I31/I32 -> 5.771188 | J30: =J31/J32 -> 6.5872282 | K30: Hay un uso eficiente del activo fijo.
B31: Ingresos | C31: ='Estado de resultados'!C32 -> 117861.89 | D31: ='Estado de resultados'!D32 -> 128579.52 | E31: ='Estado de resultados'!E32 -> 129124.71 | F31: ='Estado de resultados'!F32 -> 151524.88 | G31: ='Estado de resultados'!G32 -> 164664.44 | H31: ='Estado de resultados'!H32 -> 180766.85 | I31: ='Estado de resultados'!I32 -> 203226.68 | J31: ='Estado de resultados'!J32 -> 259326
B32: Capital contable | C32: ='Balance general'!C102 -> 37599.874 | D32: ='Balance general'!D102 -> 39124.751 | E32: ='Balance general'!E102 -> 38815.366 | F32: ='Balance general'!F102 -> 35032.073 | G32: ='Balance general'!G102 -> 34868.261 | H32: ='Balance general'!H102 -> 36183.767 | I32: ='Balance general'!I102 -> 35214.012 | J32: ='Balance general'!J102 -> 39368
B33: Rentabiidad | C33: 2015 | D33: 2016 | E33: 2017 | F33: 2018 | G33: 2019 | H33: 2020 | I33: 2021 | J33: 2022
B34: Margen de utilidad sobre ventas | C34: ='Estado de resultados'!C48/'Estado de resultados'!C32 -> 0.022759638 | D34: ='Estado de resultados'!D48/'Estado de resultados'!D32 -> 0.022704425 | E34: ='Estado de resultados'!E48/'Estado de resultados'!E32 -> 0.022382458 | F34: ='Estado de resultados'!F48/'Estado de resultados'!F32 -> 0.013668761 | G34: ='Estado de resultados'!G48/'Estado de resultados'!G32 -> 0.011873952 | H34: ='Estado de resultados'!H48/'Estado de resultados'!H32 -> 0.018279136 | I34: ='Estado de resultados'!I48/'Estado de resultados'!I32 -> 0.018462812 | J34: ='Estado de resultados'!J48/'Estado de resultados'!J32 -> 0.023815583 | K34: Se generan pocas utilidades con las ventas.
B35: Rendmiento sobre capital social | C35: =C36/C37 -> 0.071343165 | D35: =D36/D37 -> 0.074615784 | E35: =E36/E37 -> 0.074458357 | F35: =F36/F37 -> 0.059121748 | G35: =G36/G37 -> 0.056074425 | H35: =H36/H37 -> 0.091318899 | I35: =I36/I37 -> 0.10655236 | J35: =J36/J37 -> 0.15687868 | K35: Posible reducción/pérdida de mercado.
B36: Utilidad neta | C36: ='Estado de resultados'!C48 -> 2682.494 | D36: ='Estado de resultados'!D48 -> 2919.324 | E36: ='Estado de resultados'!E48 -> 2890.1284 | F36: ='Estado de resultados'!F48 -> 2071.1574 | G36: ='Estado de resultados'!G48 -> 1955.2177 | H36: ='Estado de resultados'!H48 -> 3304.2618 | I36: ='Estado de resultados'!I48 -> 3752.136 | J36: ='Estado de resultados'!J48 -> 6176
B37: Capital contable | C37: ='Balance general'!C102 -> 37599.874 | D37: ='Balance general'!D102 -> 39124.751 | E37: ='Balance general'!E102 -> 38815.366 | F37: ='Balance general'!F102 -> 35032.073 | G37: ='Balance general'!G102 -> 34868.261 | H37: ='Balance general'!H102 -> 36183.767 | I37: ='Balance general'!I102 -> 35214.012 | J37: ='Balance general'!J102 -> 39368
B38: Rendimiento sobre el patrimonio | C38: =C39/C40 -> 0.071343165 | D38: =D39/D40 -> -0.039424196 | E38: =E39/E40 -> 0.019978194 | F38: =F39/F40 -> -0.0036249534 | G38: =G39/G40 -> -0.013484604 | H38: =H39/H40 -> 0.15394307 | I38: =I39/I40 -> 0.12275618 | J38: =J39/J40 -> 0.064609404 | K38: La ROE ha mejorado en los últimos años, indicando que el dinero invertido está generando más ganancias.
B39: Utilidad neta | C39: ='Estado de resultados'!C48 -> 2682.494 | D39: ='Flujo de efectivo'!D58 -> -1542.4619 | E39: ='Flujo de efectivo'!E58 -> 775.4609 | F39: ='Flujo de efectivo'!F58 -> -126.98963 | G39: ='Flujo de efectivo'!G58 -> -470.1847 | H39: ='Flujo de efectivo'!H58 -> 5570.2403 | I39: ='Flujo de efectivo'!I58 -> 4322.7378 | J39: ='Flujo de efectivo'!J58 -> 2543.543
B40: Capital contable | C40: ='Balance general'!C102 -> 37599.874 | D40: ='Balance general'!D102 -> 39124.751 | E40: ='Balance general'!E102 -> 38815.366 | F40: ='Balance general'!F102 -> 35032.073 | G40: ='Balance general'!G102 -> 34868.261 | H40: ='Balance general'!H102 -> 36183.767 | I40: ='Balance general'!I102 -> 35214.012 | J40: ='Balance general'!J102 -> 39368
B41: Rendimiento sobre la inversión | C41: =C42/C43 -> 0.03530015 | D41: =D42/D43 -> 0.037725225 | E41: =E42/E43 -> 0.038486011 | F41: =F42/F43 -> 0.018133175 | G41: =G42/G43 -> 0.017587623 | H41: =H42/H43 -> 0.029563621 | I41: =I42/I43 -> 0.024673851 | J41: =J42/J43 -> 0.04305663 | K41: Se tiene una ROA bastante baja, lo que significa que la administración para conseguir utilidades es deficiente.
B42: Utilidad neta | C42: ='Estado de resultados'!C48 -> 2682.494 | D42: ='Estado de resultados'!D48 -> 2919.324 | E42: ='Estado de resultados'!E48 -> 2890.1284 | F42: ='Estado de resultados'!F48 -> 2071.1574 | G42: ='Estado de resultados'!G48 -> 1955.2177 | H42: ='Estado de resultados'!H48 -> 3304.2618 | I42: ='Estado de resultados'!I48 -> 3752.136 | J42: ='Estado de resultados'!J48 -> 6176
B43: Activo total | C43: ='Balance general'!C79 -> 75991.009 | D43: ='Balance general'!D79 -> 77383.872 | E43: ='Balance general'!E79 -> 75095.556 | F43: ='Balance general'!F79 -> 114219.24 | G43: ='Balance general'!G79 -> 111170.09 | H43: ='Balance general'!H79 -> 111767.83 | I43: ='Balance general'!I79 -> 152069.33 | J43: ='Balance general'!J79 -> 143439

Sheet Balance general
B1: Factor INPC | C1: =I1+42.04% -> 1.4986 | D1: =I1+37.42% -> 1.4524 | E1: =I1+28.7% -> 1.3652 | F1: =I1+22.77% -> 1.3059 | G1: =I1+19.39% -> 1.2721 | H1: =I1+15.75% -> 1.2357 | I1: =J1+7.82% -> 1.0782 | J1: 1
B3: Información del Balance General | C3: 31 de diciembre
B4: Millones de pesos | C4: 2015 | D4: 2016 | E4: 2017 | F4: 2018 | G4: 2019 | H4: 2020 | I4: 2021 | J4: 2022
B5: Efectivo | C5: 2048 | D5: 943 | E5: 1522 | F5: 1252 | G5: 984 | H5: 5445 | I5: 9101 | J5: 11566
B6: Cuentas y documentos por cobrar neto | C6: 795 | D6: 952 | E6: 1012 | F6: 1490 | G6: 1353 | H6: 1339 | I6: 2197 | J6: 1990
B7: Impuestos por recuperar | C7: 1405 | D7: 1710 | E7: 1439 | F7: 2329 | G7: 2253 | H7: 1991 | I7: 2003 | J7: 2092
B8: Cuentas por cobrar partes relacionadas | C8: 8 | D8: 22 | E8: 17 | F8: 25 | G8: 59 | H8: 34 | I8: 66 | J8: 60
B9: Instrumentos financieros derivados | D9: 22 | F9: 5 | G9: 0 | H9: 0 | I9: 0 | J9: 0
B10: Inventarios - neto | C10: 7495 | D10: 8942 | E10: 9654 | F10: 12871 | G10: 13471 | H10: 11986 | I10: 17908 | J10: 21039
B11: Pagos anticipados | E11: 288 | F11: 373 | G11: 479 | H11: 483 | I11: 867 | J11: 948
B12: Activos mantenidos para la venta | G12: 0 | H12: 0 | I12: 95 | J12: 0
B13: Total de Activo circulante | C13: =SUM(C5:C12) -> 11751 | D13: =SUM(D5:D12) -> 12591 | E13: =SUM(E5:E12) -> 13932 | F13: =SUM(F5:F12) -> 18345 | G13: =SUM(G5:G12) -> 18599 | H13: =SUM(H5:H12) -> 21278 | I13: =SUM(I5:I12) -> 32237 | J13: =SUM(J5:J12) -> 37695
B14: Inmuebles y equipo - neto | C14: 28142 | D14: 29898 | E14: 30829 | F14: 53830 | G14: 32965 | H14: 32812 | I14: 42178 | J14: 42792
B15: Activos por derechos de uso - Neto | G15: 19218 | H15: 19105 | I15: 41916 | J15: 38324
B16: Propiedades de inversión | C16: 5879 | D16: 6420 | E16: 6856 | F16: 8679 | G16: 9512 | H16: 9811 | I16: 10996 | J16: 11294
B17: Inversión en acciones asociadas | C17: 19 | D17: 17 | E17: 10 | F17: 8 | G17: 6 | H17: 139 | I17: 941 | J17: 976
B18: Cuentas por cobrar de largo plazo | C18: 94 | D18: 94 | E18: 95 | F18: 95 | G18: 471 | H18: 300 | I18: 100 | J18: 0
B19: Otros activos neto | C19: 2465 | D19: 2586 | E19: 2295 | F19: 5528 | G19: 5372 | H19: 5970 | I19: 12386 | J19: 11835
B20: Cuentas por cobrar de parte relacionada - largo plazo | C20: 37 | D20: 37 | E20: 37 | F20: 37 | G20: 37 | H20: 37 | I20: 37 | J20: 0
B21: Instrumentos financieros derivados | C21: 77 | D21: 39 | E21: 71 | F21: 90 | G21: 13 | H21: 0 | I21: 0 | J21: 268
B22: Impuestos a la utilidad diferidos | C22: 2244 | D22: 1598 | E22: 882 | F22: 852 | G22: 1198 | H22: 997 | I22: 249 | J22: 255
B23: Activos totales | C23: =SUM(C13:C22) -> 50708 | D23: =SUM(D13:D22) -> 53280 | E23: =SUM(E13:E22) -> 55007 | F23: =SUM(F13:F22) -> 87464 | G23: =SUM(G13:G22) -> 87391 | H23: =SUM(H13:H22) -> 90449 | I23: =SUM(I13:I22) -> 141040 | J23: =SUM(J13:J22) -> 143439
B24: Pasivo circulante
B25: Cuentas y documentos por pagar proveedores | C25: 12935 | D25: 14018 | E25: 14597 | F25: 18798 | G25: 17451 | H25: 18451 | I25: 26284 | J25: 29749
B26: Cuentas por pagar compañías afiliadas - Factoring corportaivo SA de CV | G26: 995 | H26: 1042 | I26: 1120 | J26: 903
B27: Prestamos de instituciones financieras | C27: 0 | D27: 205 | E27: 150 | F27: 73 | G27: 1207 | H27: 2000 | I27: 0 | J27: 0
B28: Porción circulante del pasivo a largo plazo | C28: 1960 | D28: 1107 | E28: 439 | F28: 338 | G28: 561 | H28: 1162 | I28: 177 | J28: 0
B29: Porción circulante de las obligaciones por arrendamiento | C29: 117 | D29: 64 | E29: 80 | F29: 575 | G29: 560 | H29: 602 | I29: 2177 | J29: 2329
B30: Porción circulante obligaciones relacionadas con derecho de cobro fideicomitidos | E30: 113 | F30: 122 | G30: 75 | H30: 0 | I30: 0 | J30: 0
B31: Instrumentos financieros derivados | C31: 0 | D31: 0 | E31: 0 | F31: 0 | G31: 0 | H31: 55 | I31: 0 | J31: 0
B32: Impuestos y gastos acumulados | C32: 2981 | D32: 3026 | E32: 3246 | F32: 3699 | G32: 3546 | H32: 3863 | I32: 7761 | J32: 8780
B33: Impuestos y contribuciones por pagar | F33: 432 | G33: 574 | H33: 573 | I33: 1025 | J33: 1380
B34: Total de Pasivo Circulante | C34: =SUM(C25:C32) -> 17993 | D34: =SUM(D25:D32) -> 18420 | E34: =SUM(E25:E32) -> 18625 | F34: =SUM(F25:F33) -> 24037 | G34: =SUM(G25:G33) -> 24969 | H34: =SUM(H25:H33) -> 27748 | I34: =SUM(I25:I33) -> 38544 | J34: 43141
B35: Préstamos de instituciones financieras | C35: 2893 | D35: 3927 | E35: 4476 | F35: 9716 | G35: 8733 | H35: 6186 | I35: 17391 | J35: 12682
B36: Beneficios a los empleados | C36: 478 | D36: 454 | E36: 538 | F36: 609 | G36: 892 | H36: 1073 | I36: 2869 | J36: 2292
B37: Instrumentos Financieros Derivados | C37: 100 | D37: 0 | F37: 0 | G37: 35 | H37: 253 | I37: 45 | J37: 0
B38: Obligaciones relacionadas con derecho de cobro
B39: Fideicomitidos | C39: 839 | D39: 742 | E39: 521 | F39: 405 | G39: 315 | H39: 0 | I39: 0 | J39: 0
B40: Obligaciones por arrendamiento | C40: 152 | D40: 137 | E40: 153 | F40: 22572 | G40: 21761 | H40: 22331 | I40: 44597 | J40: 41622
B41: Impuesto a la utilidad diferido | C41: 1476 | D41: 1724 | E41: 1801 | F41: 2858 | G41: 2856 | H41: 2608 | I41: 2625 | J41: 2069
...

Sheet Estado de resultados
B1: Factor INPC | C1: =I1+42.04% -> 1.4986 | D1: =I1+37.42% -> 1.4524 | E1: =I1+28.7% -> 1.3652 | F1: =I1+22.77% -> 1.3059 | G1: =I1+19.39% -> 1.2721 | H1: =I1+15.75% -> 1.2357 | I1: =J1+7.82% -> 1.0782 | J1: 1
B3: Información de Estado de Resultados | C3: 31 de diciembre
B4: Millones de pesos, excepto importes por acción y número de acciones | C4: 2015 | D4: 2016 | E4: 2017 | F4: 2018 | G4: 2019 | H4: 2020 | I4: 2021 | J4: 2022
B5: Ventas netas | C5: 78648 | D5: 88529 | E5: 94583 | F5: 116031 | G5: 129443 | H5: 146287 | I5: 188487 | J5: 259326
B6: Costo de ventas | C6: 63068 | D6: 70313 | E6: 74916 | F6: 91311 | G6: 101491 | H6: 113908 | I6: 146535 | J6: 200026
B7: Utilidad bruta | C7: 15580 | D7: 18216 | E7: 19666 | F7: 24720 | G7: 27952 | H7: 32380 | I7: 41952 | J7: 59300
B8: Gastos de operación | C8: 11901 | D8: 13961 | E8: 15248 | F8: 19558 | G8: 22376 | H8: 25446 | I8: 33204 | J8: 45554
B9: Utilidad de operación | C9: 3678 | D9: 4254 | E9: 4418 | F9: 5161 | G9: 5576 | H9: 6933 | I9: 8748 | J9: 13746
B10: Gastos por intereses | C10: 543 | D10: 647 | E10: 672 | F10: 2018 | G10: 2344 | H10: 2306 | I10: 2658 | J10: 3382
B11: Ingresos por intereses | C11: -35 | D11: -68 | E11: -72 | F11: -88 | G11: -63 | H11: -136 | I11: -135 | J11: -269
B12: Perdida (ganancia) cambiaria | C12: 5 | D12: 9 | E12: -36 | F12: 8 | G12: -56 | H12: 10 | I12: -25 | J12: -50
B13: Otros gastos financieros | C13: 526 | D13: 593 | E13: 617 | F13: 789 | G13: 885 | H13: 1006 | I13: 1356 | J13: 2049
C14: =C10+C11+C12+C13 -> 1039 | D14: =D10+D11+D12+D13 -> 1181 | E14: =E10+E11+E12+E13 -> 1181 | F14: =F10+F11+F12+F13 -> 2727 | G14: =G10+G11+G12+G13 -> 3110 | H14: =H10+H11+H12+H13 -> 3186 | I14: =I10+I11+I12+I13 -> 3854 | J14: 5112
B15: Participación en los resultados de compañías asociadas | I15: 54 | J15: 89
B16: Utilidad antes de impuesto a la utilidad | C16: 2639 | D16: 3073 | E16: 3238 | F16: 2435 | G16: 2465 | H16: 3748 | I16: 4950 | J16: 8722
B17: Impuestos a la utilidad | C17: 850 | D17: 1063 | E17: 1120 | F17: 848 | G17: 928 | H17: 1073 | I17: 1469 | J17: 2546
B18: Utilidad neta consolidada | C18: 1790 | D18: 2010 | E18: 2117 | F18: 1586 | G18: 1537 | H18: 2674 | I18: 3480 | J18: 6176
B19: Participación controladora | C19: 1740 | D19: 1953 | E19: 2079 | F19: 1638 | G19: 1566 | H19: 2589 | I19: 3420 | J19: 5997
B20: Participación no controladora | C20: 50 | D20: 57 | E20: 38 | F20: -51 | G20: -29 | H20: 85 | I20: 60 | J20: 179
B21: Utilidad neta consolidada | C21: =C18 -> 1790 | D21: =D18 -> 2010 | E21: =E18 -> 2117 | F21: =F18 -> 1586 | G21: =G18 -> 1537 | H21: =H18 -> 2674 | I21: =I18 -> 3480 | J21: 6176
B22: Promedio ponderado de acciones en circulación | C22: 963917211 | D22: 963917211 | E22: 963917211 | F22: 963917211 | G22: 963917211 | H22: 963917211 | I22: 963917211 | J22: 963917211
B23: Utilidad básica por acción ordinaria | C23: 1.8 | D23: 2 | E23: 2.2 | F23: 1.7 | G23: 1.6 | H23: 2.7 | I23: 3.5 | J23: 6.2
B24: Recursos generado por (utilizados en)
B25: Actividades de operación | C25: 4420 | D25: 3439 | E25: 5104 | F25: 6783 | G25: 5554 | H25: 12318 | I25: 16103 | J25: 18540
B26: Actividades de inverción | C26: -2735 | D26: -3358 | E26: -3093 | F26: -8840 | G26: -2845 | H26: -2536 | I26: -15622 | J26: -6481
B27: Actividades de financiamiento | C27: -415 | D27: -1143 | E27: -1442 | F27: 1960 | G27: -3079 | H27: -5274 | I27: 3528 | J27: -9516
B30: Información de Estado de Resultados | C30: 31 de diciembre | L30: Análisis vertical
B31: Millones de pesos, excepto importes por acción y número de acciones | C31: 2015 | D31: 2016 | E31: 2017 | F31: 2018 | G31: 2019 | H31: 2020 | I31: 2021 | J31: 2022 | L31: =C31 -> 2015 | M31: =D31 -> 2016 | N31: =E31 -> 2017 | O31: =F31 -> 2018 | P31: =G31 -> 2019 | Q31: =H31 -> 2020 | R31: =I31 -> 2021 | S31: =J31 -> 2022 | T31: Promedio
B32: Ventas netas | C32: =IFERROR(C$1*C5,0) -> 117861.89 | D32: =IFERROR(D$1*D5,0) -> 128579.52 | E32: =IFERROR(E$1*E5,0) -> 129124.71 | F32: =IFERROR(F$1*F5,0) -> 151524.88 | G32: =IFERROR(G$1*G5,0) -> 164664.44 | H32: =IFERROR(H$1*H5,0) -> 180766.85 | I32: =IFERROR(I$1*I5,0) -> 203226.68 | J32: =IFERROR(J$1*J5,0) -> 259326 | L32: =C32/C$32 -> 1 | M32: =D32/D$32 -> 1 | N32: =E32/E$32 -> 1 | O32: =F32/F$32 -> 1 | P32: =G32/G$32 -> 1 | Q32: =H32/H$32 -> 1 | R32: =I32/I$32 -> 1 | S32: =J32/J$32 -> 1
B33: Costo de ventas | C33: =IFERROR(C6*C$1,0) -> 94513.705 | D33: =IFERROR(D6*D$1,0) -> 102122.6 | E33: =IFERROR(E6*E$1,0) -> 102275.32 | F33: =IFERROR(F6*F$1,0) -> 119243.03 | G33: =IFERROR(G6*G$1,0) -> 129106.7 | H33: =IFERROR(H6*H$1,0) -> 140756.12 | I33: =IFERROR(I6*I$1,0) -> 157994.04 | J33: =IFERROR(J6*J$1,0) -> 200026 | L33: =C33/C$32 -> 0.80190215 | M33: =D33/D$32 -> 0.79423692 | N33: =E33/E$32 -> 0.79206623 | O33: =F33/F$32 -> 0.78695349 | P33: =G33/G$32 -> 0.78405939 | Q33: =H33/H$32 -> 0.77866113 | R33: =I33/I$32 -> 0.77742762 | S33: =J33/J$32 -> 0.77133029 | T33: =AVERAGE(L33:S33) -> 0.78582965
B34: Utilidad bruta | C34: =IFERROR(C7*C$1,0) -> 23348.188 | D34: =IFERROR(D7*D$1,0) -> 26456.918 | E34: =IFERROR(E7*E$1,0) -> 26848.023 | F34: =IFERROR(F7*F$1,0) -> 32281.848 | G34: =IFERROR(G7*G$1,0) -> 35557.739 | H34: =IFERROR(H7*H$1,0) -> 40011.966 | I34: =IFERROR(I7*I$1,0) -> 45232.646 | J34: =IFERROR(J7*J$1,0) -> 59300 | L34: =C34/C$32 -> 0.19809785 | M34: =D34/D$32 -> 0.20576308 | N34: =E34/E$32 -> 0.2079232 | O34: =F34/F$32 -> 0.21304651 | P34: =G34/G$32 -> 0.21594061 | Q34: =H34/H$32 -> 0.22134571 | R34: =I34/I$32 -> 0.22257238 | S34: =J34/J$32 -> 0.22866971 | T34: =AVERAGE(L34:S34) -> 0.21416988
B35: Gastos de operación | C35: =IFERROR(C8*C$1,0) -> 17834.839 | D35: =IFERROR(D8*D$1,0) -> 20276.956 | E35: =IFERROR(E8*E$1,0) -> 20816.57 | F35: =IFERROR(F8*F$1,0) -> 25540.792 | G35: =IFERROR(G8*G$1,0) -> 28464.51 | H35: =IFERROR(H8*H$1,0) -> 31443.622 | I35: =IFERROR(I8*I$1,0) -> 35800.553 | J35: =IFERROR(J8*J$1,0) -> 45554 | L35: =C35/C$32 -> 0.1513198 | M35: =D35/D$32 -> 0.15769974 | N35: =E35/E$32 -> 0.1612129 | O35: =F35/F$32 -> 0.1685584 | P35: =G35/G$32 -> 0.17286373 | Q35: =H35/H$32 -> 0.17394574 | R35: =I35/I$32 -> 0.17616069 | S35: =J35/J$32 -> 0.17566307 | T35: =AVERAGE(L35:S35) -> 0.16717801
B36: Utilidad de operación | C36: =IFERROR(C9*C$1,0) -> 5511.8508 | D36: =IFERROR(D9*D$1,0) -> 6178.5096 | E36: =IFERROR(E9*E$1,0) -> 6031.4536 | F36: =IFERROR(F9*F$1,0) -> 6739.7499 | G36: =IFERROR(G9*G$1,0) -> 7093.2296 | H36: =IFERROR(H9*H$1,0) -> 8567.1081 | I36: =IFERROR(I9*I$1,0) -> 9432.0936 | J36: =IFERROR(J9*J$1,0) -> 13746 | L36: =C36/C$32 -> 0.046765334 | M36: =D36/D$32 -> 0.048052051 | N36: =E36/E$32 -> 0.046710297 | O36: =F36/F$32 -> 0.044479493 | P36: =G36/G$32 -> 0.043076876 | Q36: =H36/H$32 -> 0.047393138 | R36: =I36/I$32 -> 0.046411689 | S36: =J36/J$32 -> 0.05300664
B37: Gastos por intereses | C37: =IFERROR(C10*C$1,0) -> 813.7398 | D37: =IFERROR(D10*D$1,0) -> 939.7028 | E37: =IFERROR(E10*E$1,0) -> 917.4144 | F37: =IFERROR(F10*F$1,0) -> 2635.3062 | G37: =IFERROR(G10*G$1,0) -> 2981.8024 | H37: =IFERROR(H10*H$1,0) -> 2849.5242 | I37: =IFERROR(I10*I$1,0) -> 2865.8556 | J37: =IFERROR(J10*J$1,0) -> 3382 | L37: =C37/C$32 -> 0.0069041807 | M37: =D37/D$32 -> 0.0073083396 | N37: =E37/E$32 -> 0.0071048709 | O37: =F37/F$32 -> 0.017391904 | P37: =G37/G$32 -> 0.018108357 | Q37: =H37/H$32 -> 0.015763533 | R37: =I37/I$32 -> 0.014101768 | S37: =J37/J$32 -> 0.0130415
B38: Ingresos por intereses | C38: =IFERROR(C11*C$1,0) -> -52.451 | D38: =IFERROR(D11*D$1,0) -> -98.7632 | E38: =IFERROR(E11*E$1,0) -> -98.2944 | F38: =IFERROR(F11*F$1,0) -> -114.9192 | G38: =IFERROR(G11*G$1,0) -> -80.1423 | H38: =IFERROR(H11*H$1,0) -> -168.0552 | I38: =IFERROR(I11*I$1,0) -> -145.557 | J38: =IFERROR(J11*J$1,0) -> -269 | L38: =C38/C$32 -> -0.00044502085 | M38: =D38/D$32 -> -0.00076810988 | N38: =E38/E$32 -> -0.00076123616 | O38: =F38/F$32 -> -0.00075841801 | P38: =G38/G$32 -> -0.00048670071 | Q38: =H38/H$32 -> -0.00092967933 | R38: =I38/I$32 -> -0.00071622977 | S38: =J38/J$32 -> -0.0010373044
B39: Perdida (ganancia) cambiaria | C39: =IFERROR(C12*C$1,0) -> 7.493 | D39: =IFERROR(D12*D$1,0) -> 13.0716 | E39: =IFERROR(E12*E$1,0) -> -49.1472 | F39: =IFERROR(F12*F$1,0) -> 10.4472 | G39: =IFERROR(G12*G$1,0) -> -71.2376 | H39: =IFERROR(H12*H$1,0) -> 12.357 | I39: =IFERROR(I12*I$1,0) -> -26.955 | J39: =IFERROR(J12*J$1,0) -> -50 | L39: =C39/C$32 -> 6.3574407e-05 | M39: =D39/D$32 -> 0.0001016616 | N39: =E39/E$32 -> -0.00038061808 | O39: =F39/F$32 -> 6.8947092e-05 | P39: =G39/G$32 -> -0.00043262285 | Q39: =H39/H$32 -> 6.8358774e-05 | R39: =I39/I$32 -> -0.00013263514 | S39: =J39/J$32 -> -0.00019280751
B40: Otros gastos financieros | C40: =IFERROR(C13*C$1,0) -> 788.2636 | D40: =IFERROR(D13*D$1,0) -> 861.2732 | E40: =IFERROR(E13*E$1,0) -> 842.3284 | F40: =IFERROR(F13*F$1,0) -> 1030.3551 | G40: =IFERROR(G13*G$1,0) -> 1125.8085 | H40: =IFERROR(H13*H$1,0) -> 1243.1142 | I40: =IFERROR(I13*I$1,0) -> 1462.0392 | J40: =IFERROR(J13*J$1,0) -> 2049 | L40: =C40/C$32 -> 0.0066880277 | M40: =D40/D$32 -> 0.00669837 | N40: =E40/E$32 -> 0.006523371 | O40: =F40/F$32 -> 0.0067999069 | P40: =G40/G$32 -> 0.0068369862 | Q40: =H40/H$32 -> 0.0068768927 | R40: =I40/I$32 -> 0.0071941301 | S40: =J40/J$32 -> 0.0079012517
C41: =IFERROR(C14*C$1,0) -> 1557.0454 | D41: =IFERROR(D14*D$1,0) -> 1715.2844 | E41: =IFERROR(E14*E$1,0) -> 1612.3012 | F41: =IFERROR(F14*F$1,0) -> 3561.1893 | G41: =IFERROR(G14*G$1,0) -> 3956.231 | H41: =IFERROR(H14*H$1,0) -> 3936.9402 | I41: =IFERROR(I14*I$1,0) -> 4155.3828 | J41: =IFERROR(J14*J$1,0) -> 5112 | L41: =C41/C$32 -> 0.013210762 | M41: =D41/D$32 -> 0.013340261 | N41: =E41/E$32 -> 0.012486388 | O41: =F41/F$32 -> 0.02350234 | P41: =G41/G$32 -> 0.024026019 | Q41: =H41/H$32 -> 0.021779105 | R41: =I41/I$32 -> 0.020447033 | S41: =J41/J$32 -> 0.01971264
B42: Participación en los resultados de compañías asociadas | C42: =IFERROR(C15*C$1,0) -> 0 | D42: =IFERROR(D15*D$1,0) -> 0 | E42: =IFERROR(E15*E$1,0) -> 0 | F42: =IFERROR(F15*F$1,0) -> 0 | G42: =IFERROR(G15*G$1,0) -> 0 | H42: =IFERROR(H15*H$1,0) -> 0 | I42: =IFERROR(I15*I$1,0) -> 58.2228 | J42: =IFERROR(J15*J$1,0) -> 89 | L42: =C42/C$32 -> 0 | M42: =D42/D$32 -> 0 | N42: =E42/E$32 -> 0 | O42: =F42/F$32 -> 0 | P42: =G42/G$32 -> 0 | Q42: =H42/H$32 -> 0 | R42: =I42/I$32 -> 0.00028649191 | S42: =J42/J$32 -> 0.00034319737
B43: Utilidad antes de impuesto a la utilidad | C43: =IFERROR(C16*C$1,0) -> 3954.8054 | D43: =IFERROR(D16*D$1,0) -> 4463.2252 | E43: =IFERROR(E16*E$1,0) -> 4420.5176 | F43: =IFERROR(F16*F$1,0) -> 3179.8665 | G43: =IFERROR(G16*G$1,0) -> 3135.7265 | H43: =IFERROR(H16*H$1,0) -> 4631.4036 | I43: =IFERROR(I16*I$1,0) -> 5337.09 | J43: =IFERROR(J16*J$1,0) -> 8722 | L43: =C43/C$32 -> 0.033554572 | M43: =D43/D$32 -> 0.034711789 | N43: =E43/E$32 -> 0.034234482 | O43: =F43/F$32 -> 0.020985771 | P43: =G43/G$32 -> 0.019043131 | Q43: =H43/H$32 -> 0.025620869 | R43: =I43/I$32 -> 0.026261758 | S43: =J43/J$32 -> 0.033633342
...

Sheet Flujo de efectivo
B1: Factor INPC | C1: =I1+42.04% -> 1.4986 | D1: =I1+37.42% -> 1.4524 | E1: =I1+28.7% -> 1.3652 | F1: =I1+22.77% -> 1.3059 | G1: =I1+19.39% -> 1.2721 | H1: =I1+15.75% -> 1.2357 | I1: =J1+7.82% -> 1.0782 | J1: 1
B5: Flujo de efectivo | C5: 31 de diciembre | L5: Miles de pesos | T5: Análisis vertical
A6: =10^3 -> 1000 | B6: Millones de pesos | C6: 2015 | D6: 2016 | E6: 2017 | F6: 2018 | G6: 2019 | H6: 2020 | I6: 2021 | J6: 2022 | L6: 2015 | M6: 2016 | N6: 2017 | O6: 2018 | P6: 2019 | Q6: 2020 | R6: 2021 | S6: 2022 | T6: =C6 -> 2015 | U6: =D6 -> 2016 | V6: =E6 -> 2017 | W6: =F6 -> 2018 | X6: =G6 -> 2019 | Y6: =H6 -> 2020 | Z6: =I6 -> 2021 | AA6: =J6 -> 2022 | AB6: Promedio
B7: Flujos de efectivo de actividades de operación:
B8: Utilidad antes de impuestos a la utilidad | C8: =IFERROR(L8/$A$6*C$1,0) -> 3955.0931 | D8: =IFERROR(M8/$A$6*D$1,0) -> 4462.9202 | E8: =IFERROR(N8/$A$6*E$1,0) -> 4419.8978 | F8: =IFERROR(O8/$A$6*F$1,0) -> 3179.527 | G8: =IFERROR(P8/$A$6*G$1,0) -> 3135.8792 | H8: =IFERROR(Q8/$A$6*H$1,0) -> 4630.8475 | I8: =IFERROR(R8/$A$6*I$1,0) -> 5336.5779 | J8: =IFERROR(S8/$A$6*J$1,0) -> 8722.151 | L8: 2639192 | M8: 3072790 | N8: 3237546 | O8: 2434740 | P8: 2465120 | Q8: 3747550 | R8: 4949525 | S8: 8722151 | T8: =C8/C$58 -> 2.0780843 | U8: =D8/D$58 -> -2.8933747 | V8: =E8/E$58 -> 5.6997042 | W8: =F8/F$58 -> -25.037689 | X8: =G8/G$58 -> -6.6694624 | Y8: =H8/H$58 -> 0.83135508 | Z8: =I8/I$58 -> 1.2345366 | AA8: =J8/J$58 -> 3.4291345
B9: Ajustes por: | T9: =C9/C$58 -> 0 | U9: =D9/D$58 -> 0 | V9: =E9/E$58 -> 0 | W9: =F9/F$58 -> 0 | X9: =G9/G$58 -> 0 | Y9: =H9/H$58 -> 0 | Z9: =I9/I$58 -> 0 | AA9: =J9/J$58 -> 0
B10: Depreciación y amortización | C10: =IFERROR(L10/$A$6*C$1,0) -> 1982.3915 | D10: =IFERROR(M10/$A$6*D$1,0) -> 2218.6165 | E10: =IFERROR(N10/$A$6*E$1,0) -> 2234.3218 | F10: =IFERROR(O10/$A$6*F$1,0) -> 3986.5314 | G10: =IFERROR(P10/$A$6*G$1,0) -> 4516.0326 | H10: =IFERROR(Q10/$A$6*H$1,0) -> 4694.2439 | I10: =IFERROR(R10/$A$6*I$1,0) -> 5822.5366 | J10: =IFERROR(S10/$A$6*J$1,0) -> 7680.74 | L10: 1322829 | M10: 1527552 | N10: 1636626 | O10: 3052708 | P10: 3550061 | Q10: 3798854 | R10: 5400238 | S10: 7680740 | T10: =C10/C$58 -> 1.0415878 | U10: =D10/D$58 -> -1.4383607 | V10: =E10/E$58 -> 2.8812823 | W10: =F10/F$58 -> -31.392573 | X10: =G10/G$58 -> -9.6048056 | Y10: =H10/H$58 -> 0.84273634 | Z10: =I10/I$58 -> 1.3469558 | AA10: =J10/J$58 -> 3.0197013 | AB10: =AVERAGE(T10:AA10) -> -4.1629345
B11: Otros movimientos - principalmente fluctuación cambiaria | C11: =IFERROR(L11/$A$6*C$1,0) -> 0 | D11: =IFERROR(M11/$A$6*D$1,0) -> 0 | E11: =IFERROR(N11/$A$6*E$1,0) -> 0 | F11: =IFERROR(O11/$A$6*F$1,0) -> -96.777637 | G11: =IFERROR(P11/$A$6*G$1,0) -> -7.4964853 | H11: =IFERROR(Q11/$A$6*H$1,0) -> 30.392041 | I11: =IFERROR(R11/$A$6*I$1,0) -> 48.009011 | J11: =IFERROR(S11/$A$6*J$1,0) -> -230.894 | O11: -74108 | P11: -5893 | Q11: 24595 | R11: 44527 | S11: -230894 | T11: =C11/C$58 -> 0 | U11: =D11/D$58 -> 0 | V11: =E11/E$58 -> 0 | W11: =F11/F$58 -> 0.76209084 | X11: =G11/G$58 -> 0.015943703 | Y11: =H11/H$58 -> 0.0054561455 | Z11: =I11/I$58 -> 0.011106159 | AA11: =J11/J$58 -> -0.090776527
B12: Perdida en venta de inmuebles y equipo | C12: =IFERROR(L12/$A$6*C$1,0) -> 0 | D12: =IFERROR(M12/$A$6*D$1,0) -> 0 | E12: =IFERROR(N12/$A$6*E$1,0) -> 0 | F12: =IFERROR(O12/$A$6*F$1,0) -> 0 | G12: =IFERROR(P12/$A$6*G$1,0) -> 0 | H12: =IFERROR(Q12/$A$6*H$1,0) -> 25.529562 | I12: =IFERROR(R12/$A$6*I$1,0) -> 171.90282 | J12: =IFERROR(S12/$A$6*J$1,0) -> 48.47 | Q12: 20660 | R12: 159435 | S12: 48470 | T12: =C12/C$58 -> 0 | U12: =D12/D$58 -> 0 | V12: =E12/E$58 -> 0 | W12: =F12/F$58 -> 0 | X12: =G12/G$58 -> 0 | Y12: =H12/H$58 -> 0.0045832066 | Z12: =I12/I$58 -> 0.039767117 | AA12: =J12/J$58 -> 0.019056096
B13: Otros movimientos de capital | C13: =IFERROR(L13/$A$6*C$1,0) -> 0 | D13: =IFERROR(M13/$A$6*D$1,0) -> 0 | E13: =IFERROR(N13/$A$6*E$1,0) -> 0 | F13: =IFERROR(O13/$A$6*F$1,0) -> 0 | G13: =IFERROR(P13/$A$6*G$1,0) -> 0 | H13: =IFERROR(Q13/$A$6*H$1,0) -> 0 | I13: =IFERROR(R13/$A$6*I$1,0) -> 110.43895 | J13: =IFERROR(S13/$A$6*J$1,0) -> 4.592 | Q13: 0 | R13: 102429 | S13: 4592 | T13: =C13/C$58 -> 0 | U13: =D13/D$58 -> 0 | V13: =E13/E$58 -> 0 | W13: =F13/F$58 -> 0 | X13: =G13/G$58 -> 0 | Y13: =H13/H$58 -> 0 | Z13: =I13/I$58 -> 0.02554838 | AA13: =J13/J$58 -> 0.0018053558
B14: Disposición de participación en otras sociedades | C14: =IFERROR(L14/$A$6*C$1,0) -> 0 | D14: =IFERROR(M14/$A$6*D$1,0) -> 0 | E14: =IFERROR(N14/$A$6*E$1,0) -> 0 | F14: =IFERROR(O14/$A$6*F$1,0) -> 0 | G14: =IFERROR(P14/$A$6*G$1,0) -> 0 | H14: =IFERROR(Q14/$A$6*H$1,0) -> 0 | I14: =IFERROR(R14/$A$6*I$1,0) -> 145.557 | J14: =IFERROR(S14/$A$6*J$1,0) -> 0 | R14: 135000 | S14: 0 | T14: =C14/C$58 -> 0 | U14: =D14/D$58 -> 0 | V14: =E14/E$58 -> 0 | W14: =F14/F$58 -> 0 | X14: =G14/G$58 -> 0 | Y14: =H14/H$58 -> 0 | Z14: =I14/I$58 -> 0.03367241 | AA14: =J14/J$58 -> 0
B15: Minusvalía (plusvalía) neta sobre revaluación de propiedades de inversión | C15: =IFERROR(L15/$A$6*C$1,0) -> -39.095477 | D15: =IFERROR(M15/$A$6*D$1,0) -> 76.807269 | E15: =IFERROR(N15/$A$6*E$1,0) -> -40.58057 | F15: =IFERROR(O15/$A$6*F$1,0) -> -395.96847 | G15: =IFERROR(P15/$A$6*G$1,0) -> -0.4439629 | H15: =IFERROR(Q15/$A$6*H$1,0) -> 0 | I15: =IFERROR(R15/$A$6*I$1,0) -> 0 | J15: =IFERROR(S15/$A$6*J$1,0) -> 32.815 | L15: -26088 | M15: 52883 | N15: -29725 | O15: -303215 | P15: -349 | Q15: 0 | R15: 0 | S15: 32815 | T15: =C15/C$58 -> -0.020541538 | U15: =D15/D$58 -> -0.049795247 | V15: =E15/E$58 -> -0.052330904 | W15: =F15/F$58 -> 3.1181165 | X15: =G15/G$58 -> 0.00094423086 | Y15: =H15/H$58 -> 0 | Z15: =I15/I$58 -> 0 | AA15: =J15/J$58 -> 0.012901296
B16: (Ganancia) pérdida en venta de inmuebles y equipo | C16: =IFERROR(L16/$A$6*C$1,0) -> 181.33959 | D16: =IFERROR(M16/$A$6*D$1,0) -> -22.002408 | E16: =IFERROR(N16/$A$6*E$1,0) -> 30.946354 | F16: =IFERROR(O16/$A$6*F$1,0) -> 6.1808247 | G16: =IFERROR(P16/$A$6*G$1,0) -> -83.883546 | H16: =IFERROR(Q16/$A$6*H$1,0) -> 0 | I16: =IFERROR(R16/$A$6*I$1,0) -> 0 | J16: =IFERROR(S16/$A$6*J$1,0) -> 0 | L16: 121006 | M16: -15149 | N16: 22668 | O16: 4733 | P16: -65941 | T16: =C16/C$58 -> 0.095279415 | U16: =D16/D$58 -> 0.014264474 | V16: =E16/E$58 -> 0.039907046 | W16: =F16/F$58 -> -0.048671884 | X16: =G16/G$58 -> 0.17840552 | Y16: =H16/H$58 -> 0 | Z16: =I16/I$58 -> 0 | AA16: =J16/J$58 -> 0
B17: Ingreso por intereses | C17: =IFERROR(L17/$A$6*C$1,0) -> -51.725678 | D17: =IFERROR(M17/$A$6*D$1,0) -> -98.542435 | E17: =IFERROR(N17/$A$6*E$1,0) -> -98.97427 | F17: =IFERROR(O17/$A$6*F$1,0) -> -115.38802 | G17: =IFERROR(P17/$A$6*G$1,0) -> -80.297496 | H17: =IFERROR(Q17/$A$6*H$1,0) -> -168.14046 | I17: =IFERROR(R17/$A$6*I$1,0) -> -145.29392 | J17: =IFERROR(S17/$A$6*J$1,0) -> -269.217 | L17: -34516 | M17: -67848 | N17: -72498 | O17: -88359 | P17: -63122 | Q17: -136069 | R17: -134756 | S17: -269217 | T17: =C17/C$58 -> -0.027177696 | U17: =D17/D$58 -> 0.063886464 | V17: =E17/E$58 -> -0.12763283 | W17: =F17/F$58 -> 0.90864124 | X17: =G17/G$58 -> 0.17077863 | Y17: =H17/H$58 -> -0.030185496 | Z17: =I17/I$58 -> -0.033611551 | AA17: =J17/J$58 -> -0.10584331
B18: Valuación de instrumentos financieros derivados | C18: =IFERROR(L18/$A$6*C$1,0) -> -46.98111 | D18: =IFERROR(M18/$A$6*D$1,0) -> 5.1836156 | E18: =IFERROR(N18/$A$6*E$1,0) -> 41.424264 | F18: =IFERROR(O18/$A$6*F$1,0) -> -7.6564917 | G18: =IFERROR(P18/$A$6*G$1,0) -> 39.010219 | H18: =IFERROR(Q18/$A$6*H$1,0) -> 107.79135 | I18: =IFERROR(R18/$A$6*I$1,0) -> -97.054173 | J18: =IFERROR(S18/$A$6*J$1,0) -> -102.743 | L18: -31350 | M18: 3569 | N18: 30343 | O18: -5863 | P18: 30666 | Q18: 87231 | R18: -90015 | S18: -102743 | T18: =C18/C$58 -> -0.024684806 | U18: =D18/D$58 -> -0.0033606118 | V18: =E18/E$58 -> 0.053418894 | W18: =F18/F$58 -> 0.060292258 | X18: =G18/G$58 -> -0.082967861 | Y18: =H18/H$58 -> 0.019351292 | Z18: =I18/I$58 -> -0.022452015 | AA18: =J18/J$58 -> -0.040393656
